Workbook

Sheet Master-Data-Bhaiji
G1: SECTION-B MAUJE BASUDEO PUR MALTAUJI NO 11299 PARGANE PURV BHIGO
D2: Jamabandi | E2: Rasheed | G2: Old | J2: New
A3: Sr. No | B3: Individual | C3: Name Of Land | F3: AKA | G3: Khata No | H3: Khesra No | I3: Rakba | J3: Khata No | K3: Khesra No | L3: Rakba | M3: Receipt Number | N3: Date | O3: Comment | P3: Status of Document
A4: 1 | B4: Sajhi | C4: Mandir Gharari | F4: Dada Gharari | G4: 1993 | H4: 7528 | I4: 2 Kattha + 15 Dhoor | J4: 43 | K4: 83 | O4: As per new survey Rakba is=> 0.1745 Hectare | P4: Kajaz nhi mila hai
C5: Mandir Gharari | H5: 7529 | I5: 18 Dhoor
C6: Mandir Gharari | H6: 7530 | I6: 1 Kattha + 12 Dhoor
I7: Total=> 5 Kattha + 5 Dhoor | L7: 6 Kattha
A8: 2 | B8: Sajhi | C8: Kal wala Baari | F8: Banthhu Gharari | G8: 2034 | H8: 7792 | I8: 1 Kattha + 3 Dhoor | J8: 1 Kattha + 9 Dhoor | K8: 105 | O8: As per new survey Rakba is=> 0.0265 Hectare | P8: Kewala hai
A9: 3 | B9: Sajhi | C9: Samne wala Bari | D9: 1867 | F9: Neeras Lal Ke Gharari | G9: 1867 | H9: 7576 | I9: 1 Kattha + 7 Dhoor | O9: Kewala Date: 22-09-1941 Shri Raj Narayn Lal Se | P9: 2 Kewala chahiye
C10: Samne wala Bari | F10: Neeras Lal Ke Gharari | G10: 1867 | H10: 7577 | I10: 18 Dhoor
C11: Samne wala Bari | I11: Total=> 2 Kattha + 5 Dhoor
A12: 3 | C12: Chargachhiya | D12: 1777 | F12: Ayodhyi Gharari | G12: 1777 | H12: 7546 | I12: 3 Kattha + 4 Dhoor | O12: Kewala Date: 23-04-1930 Shri Ayodhya Lal se | P12: Kewala hai
A13: 3 | C13: Chargachhiya | D13: 1839 | F13: Ayodhyi Gharari | G13: 1839 | H13: 7545 | I13: 2 Kattha + 15 Dhoor
A14: 3 | I14: Total=> 5 Kattha + 19 Dhoor
A15: 3
A16: 4 | C16: Doman Dasak Gharari | D16: 1867 | F16: Doman Das Gharari | G16: 1886 | H16: 7566 | I16: 18 Dhoor | O16: 1. 11-11-1938: Shri Raj Narayan Lal se 1/3 hissa | P16: 2 Kewala chahiye
A17: 4 | C17: Doman Dasak Gharari | F17: Doman Das Gharari | G17: 1886 | H17: 7572 | I17: 1 Kattha + 3 Dhoor | O17: 2. 04-10-1940: Shri Sukar Lal se 1/3 hissa
A18: 4 | C18: Doman Dasak Gharari | F18: Doman Das Gharari | G18: 1886 | H18: 7575 | I18: 9 Dhoor | O18: 3. 13-04-1943: Brij Bihari Lal se 1/3 hissa
A19: 4 | C19: Doman Dasak Gharari | F19: Doman Das Gharari | G19: 1886 | H19: 7586 | I19: 5 Dhoor
A20: 4 | C20: Doman Dasak Gharari | F20: Doman Das Gharari | G20: 1886 | H20: 7574 | I20: 1 Kattha + 3 Dhoor
A21: 4 | I21: Total=> 3 Kattha + 18 Dhoor
A23: 5 | C23: Jhagraua Bari | D23: 1773 | G23: 1773 | H23: 7795 | I23: 14 Dhoor | O23: 1. 29.10.1927 Shri Anup Lal Anhrathari se | P23: Court me jama hai Photo copy hai
A24: 5 | C24: Jhagraua Bari | D24: 1773 | G24: 1773 | H24: 7796 | I24: 1 kattha 12 Dhoor
A25: 5 | C25: Jhagraua Bari | I25: Total= 2 Kattha 6 Dhoor
A27: 6 | C27: Chabhacha, Singhari | G27: 1892 | H27: 1007 | I27: 3 Biggha 16 Kattha 07 Dhoor | O27: 1. 30.04.1912 Mittha se | P27: Khatiyan hai
A29: 7 | C29: Dalaan Bari | G29: 1796 | H29: 7637 | I29: 4 Kattha 16 Dhoor | J29: Belagan | O29: Eska Rasid Dalan Bala Bari sath Katata hai | P29: Bandobasti ka Khtiyan chahiye
A30: 7 | C30: Dalaan Bari | G30: 1796 | H30: 7641 | I30: 9 Dhoor | J30: Belagan
A31: 7 | C31: Dalaan Bari | G31: 1796 | H31: 7642 | I31: 3 Kattha | O31: I think already sold to Kulpati Lal Das
A32: 7 | C32: Dalaan Bari | G32: 1872 | H32: 7643 | I32: 5 Dhoor
A33: 7 | C33: Dalaan Bari | G33: 1872 | H33: 7644 | I33: 14 Dhoor
A34: 7 | I34: (Total 9 Kattha 4 Dhoor
A36: 8 | C36: Basobas (Purna Gharari) | G36: 1887 | H36: 7789 | I36: 3 Kattha 4 Dhoor | J36: Belagan | O36: Total kattha mismatched | P36: Bandobasti ka Khtiyan chahiye
A37: 8 | C37: Basobas (Purna Gharari) | G37: 1887 | H37: 7790 | I37: 18 Dhoor | J37: Belagan
I38: Total 2 Kattha 14 Purnank 2 Batta 3
G40: SECTION -A MAUJE BASUDEO PUR MUDDHALAHAPATTI TAUJI NO. 11302 PARGANE PURV BHIGO THANA DARBHANGA
A41: 1 | C41: PACHHAWARIA KALAM | G41: 2014 | H41: 735 | I41: 11 KATTHA 14 DHOOR | P41: Khatiyan Raj Darbhanga hai
A42: 1 | C42: PACHHAWARIA KALAM | G42: 2014 | H42: 7445 | I42: 5 KATTHA 1 DHOOR | P42: Khatiyan Raj Darbhanga hai
I43: 16 KATTHA 15 DHOOR
A45: 2 | C45: NASI | G45: 2014 | H45: 792 | I45: 1 BIGGHA 3 KATTHA 3 DHOOR | P45: Khatiyan Raj Darbhanga hai
A46: 3 | C46: EKA AMMA | G46: 2014 | H46: 1179 | I46: 4 KATTHA 7 DHOOR | P46: Khatiyan Raj Darbhanga hai
...

Sheet UNLal Khet-Gachhi Batwara
B1: NAME OF LAND | C1: KHATA | D1: KHASRA [OLD] | E1: KHASRA [NEW] | F1: RAKBA | I1: ACRE | J1: DECIMAL | K1: JAMABANDI | L1: Vartman Chauhaddi | P1: Raiyyat | Q1: Father's Name | R1: Last Rasheed No | S1: Last Lagan (in Rs.) | T1: Lagan Year | U1: Year of Purchage | V1: Type of document
A2: Umanath Lal | F2: Bigha | G2: Katha | H2: Dhur | L2: NORTH | M2: EAST | N2: SOUTH | O2: WEST
A3: Gachhi | B3: Pubariya Kalam | C3: 2014 | D3: 1246 | F3: 0 | G3: 1 | H3: 15 | J3: =((F3*20)*20+G3*20+H3)*$B$11 -> 7.637 | K3: 27 or 35 | L3: Bhagwan Das | M3: Kamla Devi | N3: Bhagwan Das | O3: Darbra | V3: Kewala
A4: Gachhi | B4: Pubariya Kalam | C4: 2014 | D4: 1248 | F4: 0 | G4: 3 | H4: 13 | J4: =((F4*20)*20+G4*20+H4)*$B$11 -> 15.9286 | K4: 27 or 35 | L4: Bhagwan Das | M4: Kamla Devi | N4: Bhagwan Das | O4: Darbra | V4: Kewala
A5: Gachhi | B5: Pubariya Kalam | C5: 1993 | D5: 1247 | F5: 0 | G5: 3 | H5: 9 | J5: =((F5*20)*20+G5*20+H5)*$B$11 -> 15.0558 | K5: 40 | L5: Bhagwan Das | M5: Kamla Devi | N5: Bhagwan Das | O5: Darbra | V5: Kewala
A6: Gachhi | B6: Pubariya Kalam | C6: 2033 | D6: 1249 | F6: 0 | H6: 18 | J6: =((F6*20)*20+G6*20+H6)*$B$11 -> 3.9276 | K6: 40 | L6: Bhagwan Das | M6: Kamla Devi | N6: Bhagwan Das | O6: Darbra | V6: Kewala
A7: Gachhi | B7: Ek-amma | C7: 2014 | D7: 1179 | F7: 0 | G7: 4 | H7: 7 | J7: =((F7*20)*20+G7*20+H7)*$B$11 -> 18.9834 | K7: 27 or 35 | L7: Badri Purve | M7: Pradumn | N7: Aggrawal | O7: Badri Purve | V7: Khatiyani
A8: Khet | B8: Du-amma | C8: 2014 | D8: 707 | F8: 0 | G8: 3 | H8: 3 | J8: =((F8*20)*20+G8*20+H8)*$B$11 -> 13.7466 | K8: 27 or 35 | L8: Ram Lochan Mallick | M8: Kabari wala | O8: Central School | V8: Khatiyani
A9: Khet | B9: Singhari | C9: 1892 | D9: 1007 | E9: 1419 & 1423 | F9: 1 | G9: 18 | H9: 3 | J9: =((F9*20)*20+G9*20+H9)*$B$11 -> 166.4866 | K9: 14 | L9: Kirtianand | N9: Badri Purve etc | O9: Satish Das | V9: Kewala
A11: 1 Dhur | B11: 0.2182

Sheet RNLal Khet-Gachhi Batwara
B1: NAME OF LAND | C1: KHATA | D1: KHASRA [OLD] | E1: KHASRA [NEW] | F1: RAKBA | I1: ACRE | J1: DECIMAL | K1: JAMABANDI | L1: Type of document | M1: Vartman Chauhaddi | U1: Raiyyat | V1: Father's Name | W1: Last Rasheed No | X1: Last Lagan (in Rs.) | Y1: Lagan Year | Z1: Year of Purchage
A2: Rewatinath Lal | F2: Bigha | G2: Katha | H2: Dhur | M2: NORTH | N2: EAST | O2: SOUTH | P2: WEST | Q2: NORTH | R2: EAST | S2: SOUTH | T2: WEST
A3: Gachhi | B3: Pachhwariya Kalam | C3: 2014 | D3: 735 | F3: 0 | G3: 11 | H3: 14 | J3: =((F3*20)*20+G3*20+H3)*$B$9 -> 51.0588 | K3: 27 or 35 | L3: Khatiyani | M3: Brij Bihari Lal Das | N3: Chuman Das | O3: Nij | P3: Khedru Das | Q3: Godown | R3: Visho Singh | S3: Nij | T3: Arvind | U3: Visheshwar Lal Das Wo Rameshwar Lal Das | V3: Jalpa Dutt Lal Das | W3: 27/811197 35/811198 | X3: 27/95.50 35/68.60 | Y3: 1997
A4: Gachhi | B4: Pachhwariya Kalam | C4: 2014 | D4: 7445 | F4: 0 | G4: 5 | H4: 1 | J4: =((F4*20)*20+G4*20+H4)*$B$9 -> 22.0382 | K4: 27 or 35 | L4: Khatiyani | M4: Nij | N4: Babu Nath Das | O4: Jagat Singh Das | P4: Kunjvati | Q4: Nij | R4: Sanotosh Sudhir Ram | S4: Ajay Lal Das | T4: Arvind | U4: Visheshwar Lal Das Wo Rameshwar Lal Das | V4: Jalpa Dutt Lal Das | W4: 27/811197 35/811198 | X4: 27/95.50 35/68.60 | Y4: 1997
A5: Khet | B5: Du-amma | C5: 2014 | D5: 707 | F5: 0 | G5: 0 | H5: 0 | J5: =((F5*20)*20+G5*20+H5)*$B$9 -> 0 | K5: 27 or 35 | L5: Khatiyani
A6: Khet | B6: Nashi Upper | C6: 2014 | D6: 790 | F6: 0 | G6: 12 | H6: 12 | J6: =((F6*20)*20+G6*20+H6)*$B$9 -> 54.9864 | K6: 35 | L6: Khatiyani | M6: Badri Purve, Shiv ji | N6: Darbhanga Public School | O6: Mohan Jha | P6: Mohan Jha
A7: Khet | B7: Nashi Neecha | C7: 2014 | D7: 792 | F7: 1 | G7: 3 | H7: 3 | I7: 1 | J7: 0.017 | K7: 35 | L7: Khatiyani | M7: Badri Purve, Shiv ji | N7: Darbhanga Public School | O7: Mohan Jha | P7: Railway
A9: 1 Dhur | B9: 0.2182

Sheet LNLal Khet-Gachhi Batwara
B1: NAME OF LAND | C1: KHATA | D1: KHASRA [OLD] | E1: KHASRA [NEW] | F1: RAKBA | I1: ACRE | J1: DECIMAL | K1: JAMABANDI | L1: Type of document | M1: Vartman Chauhaddi | Q1: Raiyyat | R1: Father's Name | S1: Last Rasheed No | T1: Last Lagan (in Rs.) | U1: Lagan Year | V1: Year of Purchage
A2: Lekhnath Lal | F2: Bigha | G2: Katha | H2: Dhur | M2: NORTH | N2: EAST | O2: SOUTH | P2: WEST
A3: Gachhi | B3: Chargachhiya | C3: 1839 | D3: 7545 | F3: 0 | G3: 2 | H3: 15 | I3: 0 | J3: =((F3*20)*20+G3*20+H3)*$B$11 -> 12.001 | K3: 168 | L3: Kewala | M3: Nij | N3: Rasta | O3: Rasta | P3: Subodh Paswan
A4: Gachhi | B4: Chargachhiya | C4: 1777 | D4: 7546 | F4: 0 | G4: 3 | H4: 4 | I4: 0 | J4: =((F4*20)*20+G4*20+H4)*$B$11 -> 13.9648 | K4: 167 | L4: Kewala | N4: Rasta | O4: Nij | P4: Dabra
A5: Gachhi | B5: Murdahiya | C5: 1889 | D5: 1187 | E5: 1583 | F5: 0 | G5: 2 | H5: 15 | I5: 0 | J5: =((F5*20)*20+G5*20+H5)*$B$11 -> 12.001 | K5: 103 | L5: Kewala
A6: Gachhi | B6: Murdahiya | C6: 1989 | D6: 1190 | E6: 1588 | F6: 0 | G6: 6 | H6: 0 | I6: 0 | J6: =((F6*20)*20+G6*20+H6)*$B$11 -> 26.184 | K6: 81 | L6: Kewala | M6: Radha Mahaseth | N6: Radha Mahaseth | O6: Radha Mahaseth | P6: Raj Darbhanga
A7: Gachhi | B7: Konhi | C7: 2039 | D7: 1189 | E7: 1586 | F7: 0 | G7: 0 | H7: 0 | I7: 0 | J7: =((F7*20)*20+G7*20+H7)*$B$11 -> 0 | K7: 82 | L7: Kewala
A8: Khet | B8: Du-amma [SIKMI] | C8: 2014 | D8: 707 | F8: 0 | G8: 0 | H8: 0 | I8: 0 | J8: =((F8*20)*20+G8*20+H8)*$B$11 -> 0 | K8: 27 or 35 | L8: Khatiyani
A9: Khet | B9: Singhari | C9: 1892 | D9: 1007 | E9: 1419 & 1423 | F9: 1 | G9: 18 | H9: 3 | I9: 1 | J9: 65.477 | K9: 14 | L9: Kewala
A11: 1 Dhur | B11: 0.2182
A14: Konhi | B14: 1189 or 1197

Sheet Lekh Nath Lal-SONS
A1: LEKHNATH LAL
A2: Name | B2: Khata No | C2: Khesra | D2: Bigha | E2: Katha | F2: Dhur | G2: Dhurki | I2: Acre | J2: Decimal | K2: Hectare | M2: NORTH | N2: EAST | O2: SOUTH | P2: WEST
A3: KIRTIANAND LAL
B4: 1887 | C4: 7789 | J4: 0.02 | M4: Rewati Nath Lal | N4: Brahmanand Lal | O4: Niji Rasta 10 ft | P4: Rasta
B5: 1887 | C5: 7790 | J5: 0.02
B6: 1839 | C6: 7545 | J6: 0.3.54 | M6: Vedanand Lal | N6: Rasta | O6: Brahmanand Lal | P6: Subodh Paswan
B7: 1777 | C7: 7546 | J7: 0.04 | M7: Dabra | N7: Brahmanand Lal | O7: Niji Rasta 10 ft | P7: Vedanand Lal
B8: 1773 | C8: 7795 | J8: 0.2.50 | M8: Niji Rasta 10 ft | N8: Rasta | O8: Rakhi Das | P8: Brahmanand Lal
B9: 892 | C9: 1419 | J9: 0.54.80 | M9: Parti | N9: Parti | O9: Jeevanand Lal | P9: Vedanand Lal
B10: 892 | C10: 1588 | J10: 0.6.55 | M10: Radha Mahaseth | N10: Vedanand Lal | O10: Radha Mahaseth | P10: Sushila Devi
A12: VEDANAND LAL
B13: 1887 | C13: 7574 | J13: 0.5.73 | M13: Jeevanand Lal | N13: Khesra No: 7578 | O13: Rewati Nath Lal | P13: Rasta
B14: 1839 | C14: 7545 | J14: 0.3.54 | M14: Niji Rasta 10 ft | N14: Rasta Dhalayee | O14: Kirtianand Lal | P14: Subodh Paswan
B15: 1777 | C15: 7546 | J15: 0.04 | M15: Dabra | N15: Kirtianand Lal | O15: Subodh Paswan | P15: Dabra
B16: 892 | C16: 1419 | J16: 0.30.78 | M16: Parti | N16: Kirtianand Lal | O16: Raju Purve | P16: Brahmanand Lal
B17: 892 | C17: 1588 | J17: 0.3.38 | M17: Radha Mahaseth | N17: Brahmanand Lal | O17: Radha Mahaseth | P17: Kirtianand Lal
A19: BRAHMANAND LAL
B20: 1887 | C20: 7789 | J20: 0.04 | M20: Rewati Nath Lal | N20: Dhalayee | O20: Niji Rasta 10 ft | P20: Kirtianand Lal
B21: 1773 | C21: 7795 | J21: 0.01 | M21: Rewati Nath Lal Wo Nij Rasta | N21: Kirtianand Lal | O21: Rakhi Das | P21: Raj Kishor Bhagat
B22: 1773 | C22: 7796 | J22: 0.1.60
B23: 1839 | C23: 7545 | J23: 0.3.54 | M23: Kirtianand Lal | N23: Rasta Dhalayee | O23: Rasta | P23: Subodh Paswan
B24: 1777 | C24: 7546 | J24: 0.04 | M24: Dabra | N24: Rasta Dhalayee | O24: Niji Rasta 10 ft | P24: Kirtianand Lal
B25: 892 | C25: 1419 | J25: 0.30.78 | M25: Parti | N25: Vedanand Lal | O25: Raju Purve | P25: Parti
B26: 892 | C26: 1588 | J26: 0.3.38 | M26: Radha Mahaseth | N26: Radha Mahaseth | O26: Radha Mahaseth | P26: Brahmanand Lal

Sheet R. N. Lal
A1: REWATI NATH LAL | C1: Khesra No
A2: Name of Land | B2: Khata No | C2: Old | D2: New | E2: Bigha | F2: Katha | G2: Dhur | H2: Dhurki | J2: Acre | K2: Decimal | L2: Hectare | N2: Uttar | O2: Dakshin | P2: Purab | Q2: Pashchim
A3: BASOWASAK ANSH | B3: 1887 | C3: 7789,7790 | D3: 871 | E3: 0 | F3: 1 | G3: 10 | J3: =(K3/' DISCUSSED WITH AMEEN'!I$15) -> 0.065453455 | K3: =((E3*20)*20+F3*20+G3)*' DISCUSSED WITH AMEEN'!G$15 -> 6.546
A5: PHOOL WALA BARIK ANSK | B5: ? | C5: 7576 | E5: 0 | F5: 2 | G5: 0 | J5: =(K5/' DISCUSSED WITH AMEEN'!I$15) -> 0.087271273 | K5: =((E5*20)*20+F5*20+G5)*' DISCUSSED WITH AMEEN'!G$15 -> 8.728
A7: BAARI SAMNE | B7: 1867 | C7: 7576 | E7: 0 | F7: 1 | G7: 11 | H7: 56 | J7: =(K7/' DISCUSSED WITH AMEEN'!I$15) -> 0.067635236 | K7: =((E7*20)*20+F7*20+G7)*' DISCUSSED WITH AMEEN'!G$15 -> 6.7642
C8: 7553,7574
A11: KHAZOOR WALA BARI | B11: 110 | C11: 7795
B12: 110 | C12: 7796 | E12: 0 | F12: 1 | G12: 3 | J12: =(K12/' DISCUSSED WITH AMEEN'!I$15) -> 0.050180982 | K12: =((E12*20)*20+F12*20+G12)*' DISCUSSED WITH AMEEN'!G$15 -> 5.0186
A15: NASI KE NICHA | B15: 2014 | C15: 792 | E15: 1 | F15: 3 | G15: 3 | J15: =(K15/' DISCUSSED WITH AMEEN'!I$15) -> 1.010165 | K15: =((E15*20)*20+F15*20+G15)*' DISCUSSED WITH AMEEN'!G$15 -> 101.0266
A16: NASI KE UPAR | B16: 2014 | C16: 790 | E16: 0 | F16: 12 | G16: 12 | J16: =(K16/' DISCUSSED WITH AMEEN'!I$15) -> 0.54980902 | K16: =((E16*20)*20+F16*20+G16)*' DISCUSSED WITH AMEEN'!G$15 -> 54.9864
A19: PACHHAWARIA KALAM | B19: 2014 | C19: 735 | E19: 0 | F19: 11 | G19: 14 | J19: =(K19/' DISCUSSED WITH AMEEN'!I$15) -> 0.51053695 | K19: =((E19*20)*20+F19*20+G19)*' DISCUSSED WITH AMEEN'!G$15 -> 51.0588
B20: 2014 | C20: 7445 | E20: 0 | F20: 5 | G20: 1 | J20: =(K20/' DISCUSSED WITH AMEEN'!I$15) -> 0.22035996 | K20: =((E20*20)*20+F20*20+G20)*' DISCUSSED WITH AMEEN'!G$15 -> 22.0382
A22: SIKMI [SOLD] | C22: 707 | F22: 4 | G22: 3 | J22: =(K22/' DISCUSSED WITH AMEEN'!I$15) -> 0.18108789 | K22: =((E22*20)*20+F22*20+G22)*' DISCUSSED WITH AMEEN'!G$15 -> 18.1106
A24: GRAND TOTAL | E24: 3 | F24: 2 | G24: 17 | J24: =(K24/' DISCUSSED WITH AMEEN'!I$15) -> 2.7424998 | K24: =((E24*20)*20+F24*20+G24)*' DISCUSSED WITH AMEEN'!G$15 -> 274.2774
A26: NET TOTAL | E26: 2 | F26: 18 | G26: 14 | J26: =(K26/' DISCUSSED WITH AMEEN'!I$15) -> 2.5614119 | K26: =((E26*20)*20+F26*20+G26)*' DISCUSSED WITH AMEEN'!G$15 -> 256.1668

Sheet U. N. Lal
A1: UMANANTH LAL
A2: Name of Land | B2: Khata | C2: Khesra No | D2: Rakba
A3: DALAN WALA BARI | C3: 742, 443 | D3: 4 KATTHA 7 DHOOR
A4: BEL WALA BARI | C4: 126 | D4: 1 KATTHA 1 PURNAK 3 BATTA 4
A5: TOTAL | D5: 5 KATTHA 8 PURNAK 3 BATTA 4
A7: Mandir wala baari | D7: 2 KATTHA 15 DHOOR
A8: Chabhacha, Singhari | D8: 2 BIGHA [APPROX]
A9: Kaal wala baari
A10: Lal Didi wala baari | C10: 114/7578
A11: PUBARIA KALAM | B11: 2014 | C11: 1246 | D11: 2 KATTHA 15 DHOOR
A12: PUBARIA KALAM | B12: 2014 | C12: 1248 | D12: 3 KATTH 13 DHOOR
A13: PUBARIA KALAM | B13: 1993 | C13: 1247 | D13: 3 KATTHA 9 DHOOR
A14: PUBARIA KALAM | B14: 2033 | C14: 1249 | D14: 18 DHOOR
A15: TOTAL | D15: 10 KATTHA 15 DHOOR
A17: DU AMMA (SIKMI) | B17: 2014 | C17: 707 | D17: 11 KATTHA 9 DHOOR
A18: EKA AMMA | B18: 2014 | C18: 1179 | D18: 4 KATTHA 7 DHOOR
A19: Samne wala baari | D19: 19 DHUR

Sheet Sheet4
A1: 1 | B1: Mandir Gharari | C1: Dada Gharari | D1: 1993 | E1: 7528 | F1: 2 Kattha + 15 Dhoor
B2: Mandir Gharari | D2: 1993 | E2: 7529 | F2: 18 Dhoor
B3: Mandir Gharari | D3: 1993 | E3: 7530 | F3: 1 Kattha + 12 Dhoor
B4: Mandir Gharari | D4: 1993 | F4: Total=> 5 Kattha + 5 Dhoor
A5: 2 | B5: Kal wala Baari | C5: Banthhu Gharari | D5: 2034 | E5: 7792 | F5: 1 Kattha + 3 Dhoor
A6: 3 | B6: Samne wala Bari | C6: Neeras Lal Ke Gharari | D6: 1867 | E6: 7576 | F6: 1 Kattha + 7 Dhoor
B7: Samne wala Bari | C7: Neeras Lal Ke Gharari | E7: 7577 | F7: 18 Dhoor
B8: Samne wala Bari | F8: Total=> 2 Kattha + 5 Dhoor
A9: 3 | B9: Samne wala Bari | C9: Ayodhyi Gharari | D9: 1777 | E9: 7546 | F9: 3 Kattha + 4 Dhoor
A10: 3 | B10: Samne wala Bari | C10: Ayodhyi Gharari | D10: 1839 | E10: 7545 | F10: 2 Kattha + 15 Dhoor
A11: 3 | B11: Samne wala Bari | F11: Total=> 5 Kattha + 19 Dhoor
A12: 4 | B12: Doman Dasak Gharari | C12: Doman Das Gharari | D12: 1886 | E12: 7566 | F12: 18 Dhoor
A13: 4 | B13: Doman Dasak Gharari | C13: Doman Das Gharari | D13: 1886 | E13: 7572 | F13: 1 Kattha + 3 Dhoor
A14: 4 | B14: Doman Dasak Gharari | C14: Doman Das Gharari | D14: 1886 | E14: 7575 | F14: 9 Dhoor
A15: 4 | B15: Doman Dasak Gharari | C15: Doman Das Gharari | D15: 1886 | E15: 7586 | F15: 5 Dhoor
A16: 4 | B16: Doman Dasak Gharari | C16: Doman Das Gharari | D16: 1886 | E16: 7574 | F16: 1 Kattha + 3 Dhoor
A17: 4 | F17: Total=> 3 Kattha + 18 Dhoor
A18: 5 | B18: Jhagraua Bari | D18: 1773 | E18: 7794 | F18: 14 Dhoor
A19: 5 | B19: Jhagraua Bari | D19: 1773 | E19: 7796 | F19: 1 kattha 12 Dhoor
A20: 5 | B20: Jhagraua Bari | F20: Total= 2 Kattha 6 Dhoor
A22: 6 | B22: Chabhacha, Singhari | D22: 1892 | E22: 1007 | F22: 3 Biggha 16 Kattha 07 Dhoor
A24: 7 | B24: Dalaan Bari | D24: 1796 | E24: 7637 | F24: 4 Kattha 16 Dhoor
A25: 7 | B25: Dalaan Bari | D25: 1796 | E25: 7641 | F25: 9 Dhoor
A26: 7 | B26: Dalaan Bari | D26: 1796 | E26: 7642 | F26: 3 Kattha
A27: 7 | B27: Dalaan Bari | D27: 1872 | E27: 7643 | F27: 5 Dhoor
A28: 7 | B28: Dalaan Bari | D28: 1872 | E28: 7644 | F28: 14 Dhoor
A29: 7 | F29: (Total 9 Kattha 4 Dhoor
A30: 8 | B30: Basobas (Purna Gharari) | D30: 1887 | E30: 7789 | F30: 3 Kattha 4 Dhoor
A31: 8 | B31: Basobas (Purna Gharari) | D31: 1887 | E31: 7790 | F31: 18 Dhoor
F32: Total 2 Kattha 14 Purnank 2 Batta 3
A33: 1 | B33: PACHHAWARIA KALAM | D33: 2014 | E33: 735 | F33: 11 KATTHA 14 DHOOR
A34: 1 | B34: PACHHAWARIA KALAM | D34: 2014 | E34: 7445 | F34: 5 KATTHA 1 DHOOR
F35: 16 KATTHA 15 DHOOR
A36: 2 | B36: NASI | D36: 2014 | E36: 792 | F36: 1 BIGGHA 3 KATTHA 3 DHOOR
A37: 3 | B37: EKA AMMA | D37: 2014 | E37: 1179 | F37: 4 KATTHA 7 DHOOR
A38: 4 | B38: NASI KE UPAR | D38: 2014 | E38: 790 | F38: 12 KATTHA 12 DHOOR
A39: 5 | B39: DU AMMA (SIKMI) | D39: 2014 | E39: 707 | F39: 11 KATTHA 9 DHOOR
A40: 6 | B40: PUBARIA KALAM | D40: 2014 | E40: 1246 | F40: 2 KATTHA 15 DHOOR
A41: 7 | B41: PUBARIA KALAM | D41: 2014 | E41: 1248 | F41: 3 KATTH 13 DHOOR
A42: 8 | B42: PUBARIA KALAM | D42: 1993 | E42: 1247 | F42: 3 KATTHA 9 DHOOR
...

Sheet Misc Batwara
C1: Old Khata: 2014
B2: Name of Land | C2: Khata No | D2: Khesra No | E2: Rakba( IN decimal) | F2: IN HECTARE
A3: Lekhnath Lal Das & Umanath Lal Das & Rewati Nath Lal s/o Rameshwar Lal Das Ans sman | C3: 1892 | D3: 1419 | E3: 2.67 D | F3: 1.080
C4: 1892 | D4: 1423 | E4: 0.62 D | F4: 0.251
C5: 1892 | D5: 1541 | E5: 0.92 D | F5: 0.376
C6: 1892 | D6: 1544 | E6: 0.53 D | F6: 0.214
C7: 1892 | D7: 1572 | E7: 0.18 D | F7: 0.073
C8: 1892 | D8: 1583 | E8: 0.12 D | F8: 0.049
C9: 1892 | D9: 1586 | E9: 0.14 D | F9: 0.057
C10: 1892 | D10: 1588 | E10: 0.23 D | F10: 0.093
E11: 5 Acre 42 D | F11: 2.193
B14: Name of Land | C14: Khata No | D14: Khesra No | E14: Rakba( IN decimal) | F14: IN HECTARE | G14: Type of Land
A15: Lekhnath Lal Das & Umanath Lal Das & Rewati Nath Lal s/o Rameshwar Lal Das Ans sman | C15: 183/1616 | D15: 1419/1007 Ansh | E15: 0.46 D | G15: Dhanhar 2
D16: 1423/1007 Ansh | E16: 0.62 D | G16: Dhanhar 2
D17: 1541/792 | E17: 0.93 D | G17: Dhanhar 2
D18: 1544/790 | E18: 0.53 D | G18: Dhanhar 2
D19: 1572/1179 | E19: 0.18 D | G19: Bheeth
D20: 1583/1187 | E20: 0.12 D | G20: Bheeth
B22: Name of Land | C22: Khata No | D22: Khesra No | E22: Rakba( IN decimal) | F22: IN HECTARE | G22: Type of Land
A23: Lekhnath Lal Das & Umanath Lal Das & Rewati Nath Lal s/o Rameshwar Lal Das Ans sman | C23: 1615 | D23: 1586/1198 | E23: 0.14 D | G23: Bheeth
D24: 1588/1190 | E24: 0.23 D | G24: Bheeth
B29: Name of Land | C29: Khata No | D29: Khesra No | E29: Rakba( IN decimal) | F29: IN HECTARE | G29: Type of Land
A30: Umanath Lal Das & Rewati Nath Lal s/o Rameshwar Lal Das 2 ans sman & Vedanand Lal, Kirtianand Lal, Brahmanand Lal s/o Lekhnath Lal 1 ans saman | C30: 43 | D30: 83/7529,7530,7528 ansh | F30: 0.1230 [0.1745] | G30: Mandir pachhu gharari
D31: 105/7792 | F31: 0.0265 | G31: Kaal wala baari
D32: 112/7578,7553,7574,7576 | F32: 0.0415 | G32: Samne wala baari
D33: 114/7578 | F33: 0.0145 [0.0120] | G33: Lal didi lag gharari
D34: 126/7566 | F34: 0.0205 | G34: Bel baari enaar
D35: 208/(1246,1247,1248,1249) [7546,7547,7548,7549] TBD | F35: 0.2025 | G35: Pubariya baari samne
B37: Name of Land | C37: Khata No | D37: Khesra No | E37: Rakba( IN decimal) | F37: IN HECTARE | G37: Type of Land
A38: Umanath Lal Das & Rewati Nath Lal s/o Rameshwar Lal Das 2 ans sman & Vedanand Lal, Kirtianand Lal, Brahmanand Lal s/o Lekhnath Lal 1 ans saman | C38: 47 | D38: 842/(7642,7643,7644) | F38: 0.0520 [0.0505] | G38: Dalan wala baari bauwa kaka
C39: 47 | D39: 843/(7637,7642,7641) | F39: 0.075 | G39: Dalan wala baari bauwa kaka
F40: 0.0005 | G40: Dalan wala baari bauwa kaka
F41: 0.0025 | G41: Dalan wala baari bauwa kaka
F42: 0.0075 | G42: Dalan wala baari bauwa kaka
F43: 0.0090 | G43: Dalan wala baari bauwa kaka
C44: 47 | D44: 844/(7637) | F44: 0.0330 | G44: Dalan wala baari Bhaiya Kakka
C45: 47 | D45: 868/(7576) | F45: 0.0390 | G45: Samne Gharari 1
B47: Name of Land | C47: Khata No | D47: Khesra No | E47: Rakba( IN decimal) | F47: IN HECTARE | G47: Type of Land
C48: 46 | D48: 871(7789,7790) | F48: 0.305 | G48: Basowas
A49: Umanath Lal Das & Rewati Nath Lal s/o Rameshwar Lal Das 10 ans sman & Vedanand Lal, Kirtianand Lal, Brahmanand Lal s/o Lekhnath Lal 5 ans saman & Baijnath Lal Das, Narendra Lal Das s/o Singheswar Lal Das 3 Ans saman | F49: 0.2015 | G49: Basowas
...

Sheet Aapsi Batwara
B1: LEKHNATH LAL
B2: Name of Land | C2: Khesra No | D2: Rakba
B3: BASOWASAK ANSH | C3: 871 | D3: 1 KATTHA 11 DHOOR
B4: KHAJOOR WALA BARI | C4: 110 | D4: 2 KATTHA 7 PURNANK 3 BATTA 4
B5: DAI GHARARI | C5: 105 | D5: 1 KATTHA 3 DHOOR
B6: TALE MISHR GHARARI | C6: 7656/7658 | D6: 2 KATTHA
B7: TOTAL | D7: 7 KATTHA 1 PURNAK 3 BATTA 4
B9: SONS
B10: Vedanand Lal
B11: Kirtianand Lal
B12: Brahmanand Lal
B14: UMANANTH LAL
B15: Name of Land | C15: Khesra No | D15: Rakba
B16: DALAN WALA BARI | C16: 742, 443 | D16: 4 KATTHA 7 DHOOR
B17: BEL WALA BARI | C17: 126 | D17: 1 KATTHA 1 PURNAK 3 BATTA 4
B18: PHOOL WALAK ANSH | C18: 844 | D18: 1 KATTHA 8 DHOOR
B19: TOTAL | D19: 6 KATTHA 16 PURNAK 3 BATTA 4
B21: SONS
B22: Jiwananad
B23: Jayanand
B24: Krishnanand
B25: Dharmanand
B27: REWATI NATH LAL
B28: Name of Land | C28: Khesra No | D28: Rakba
B29: BASOWASAK ANSH | C29: 871 | D29: 1 KATTHA 11 DHOOR
B30: PHOOL WALA BARIK ANSK | D30: 8 DHOOR
B31: BAARI SAMNE | C31: 868 | D31: 4 KATTHA 4 PURNAK 3 BATTA 4
C32: 112
B33: KAPILESHWAR BABA BAARI | C33: 114 | D33: 13 DHOOR
B34: TOTAL | D34: 6 KATTHA 16 PURNAK 3 BATTA 4

Sheet  DISCUSSED WITH AMEEN
A1: 1 | B1: Naapi
A2: 1 | B2: New khesra number as per old khesra
A3: 2 | B3: Receipt as per khesra number
A4: 3 | B4: To arrange Maps of all the lands as per existing survey | D4: MAP-BASUDEOPUR SHET NO. 2 | E4: 1419 | F4: 2A67D | G4: =((2*100.01)+67) -> 267.02
A5: 4 | B5: Batwara among all the brothers | E5: 1423 | F5: 62D | G5: 62
A6: 5 | B6: Sahmati patra draft proccess | G6: =SUM(G4:G5) -> 329.02 | H6: =((G6/100.01)/2)/3 -> 0.54831184
A7: 6 | B7: What is the next process after sahmati patra for raseed
A8: 7 | B8: How to generate new raseed | F8: 65
A9: 8 | B9: Does any land doc required? How to retrieve these docs?
F11: 3 | G11: 16 | H11: 7
F12: =(76/2) -> 38
B14: 1 Katha | C14: 4.36 Decimal | F14: Dhur | G14: Decimal | H14: Acre | I14: Decimal
F15: 1 | G15: 0.2182 | H15: 1 | I15: 100.01

Sheet Old-New Khesra
A1: MAUJA- BASUDEOPUR THANA NO ANCHAL LATE LEKHNATH LAL DAS LATE RAMESHWAR LAL DAS
A2: 449 DARBHANGA DISTT DARBHANGA SON-VEDANAND LAL, KIRTIAND LAL AND BRAHMA NAND LAL
D3: RAKBA | E3: RAKBA | F3: RAKBA | G3: RAKBA | J3: NOT FINAL
A4: S.NO | B4: KHESRA NO | C4: KHATA NO | D4: BIGGHA | E4: KATTHA | F4: DHOOR | G4: DHURKI | H4: New KHESRA NO | I4: ALL NEW KHESRA NO. | J4: Name Of Land
A5: 1 | B5: 707 | C5: 2014 | D5: 0 | E5: 11 | F5: 9 | G5: 0 | H5: SHEET NO 2 WARD ME RAILWAY LINE KE DAKSHIN | I5: *1419,1423,1541,1544,1572,1583,1586,1588,83,105,112,114,126,205,842,843,844,868,771,180,450,735,497,498. | J5: DU AMMA (SIKMI)
A6: 2 | B6: 735 | C6: 2014 | D6: 0 | E6: 11 | F6: 14 | G6: 0 | H6: SHEET NO 2 WARD ME RAILWAY LINE KE DAKSHIN | J6: PACHHAWARIA KALAM
A7: 3 | B7: 767 | C7: 1985 | D7: 0 | E7: 5 | F7: 19 | G7: 0 | H7: SHEET NO 2 WARD ME RAILWAY LINE KE UTTAR | J7: POKHARI KAAT
A8: 4 | B8: 790 | C8: 2014 | D8: 0 | E8: 12 | F8: 12 | G8: 0 | H8: SHEET NO 2 WARD ME RAILWAY LINE KE UTTAR | J8: NASI KE UPAR
A9: 5 | B9: 792 | C9: 2014 | D9: 1 | E9: 3 | F9: 3 | G9: 0 | H9: SHEET NO 2 WARD ME RAILWAY LINE KE UTTAR | J9: NASI
A10: 6 | B10: 1007 | C10: 1892 | D10: 3 | E10: 16 | F10: 7 | G10: 0 | H10: *1423,1411,1457,1411,1458 | J10: Chabhacha, Singhari
A11: 7 | B11: 1179 | C11: 2014 | D11: 0 | E11: 4 | F11: 7 | G11: 0 | H11: *1572 | J11: EKA AMMA
A12: 8 | B12: 1187 | C12: 1889 | D12: 0 | E12: 2 | F12: 15 | G12: 0 | H12: 1583 | J12: KHARAHORI
A13: 9 | B13: 1189 | C13: 2039 | D13: 0 | E13: 2 | F13: 6 | G13: 0 | H13: 1585 | J13: KONHI
A14: 10 | B14: 1190 | C14: 1889 | D14: 0 | E14: 6 | F14: 0 | G14: 0 | H14: *1587 SE 1592 | J14: KHARAHORI
A15: 11 | B15: 1246 | C15: 2014 | D15: 0 | E15: 2 | F15: 15 | G15: 0 | H15: WARD NO. 2 CHADAR 2 PLUS 3 ME 150-250 | J15: PUBARIA KALAM
A16: 12 | B16: 1247 | C16: 1993 | D16: 0 | E16: 3 | F16: 9 | G16: 0 | H16: WARD NO. 2 CHADAR 2 PLUS 3 ME 150-250 | J16: PUBARIA KALAM
A17: 13 | B17: 1248 | C17: 2014 | D17: 0 | E17: 3 | F17: 13 | G17: 0 | H17: WARD NO. 2 CHADAR 2 PLUS 3 ME 150-250 | J17: PUBARIA KALAM
A18: 14 | B18: 1249 | C18: 2033 | D18: 0 | E18: 0 | F18: 18 | G18: 0 | H18: WARD NO. 2 CHADAR 2 PLUS 3 ME 150-250 | J18: PUBARIA KALAM
A19: 15 | B19: 7445 | C19: 2014 | D19: 0 | E19: 5 | F19: 1 | G19: 0 | J19: PACHHAWARIA KALAM
A20: 16 | B20: 7528 | C20: 1993 | D20: 0 | E20: 2 | F20: 15 | G20: 0 | J20: DADA GHARARI
A21: 17 | B21: 7529 | C21: 1993 | D21: 0 | E21: 0 | F21: 18 | G21: 0 | J21: DADA GHARARI
A22: 18 | B22: 7530 | C22: 1993 | D22: 0 | E22: 1 | F22: 12 | G22: 0 | J22: DADA GHARARI
A23: 19 | B23: 7545 | C23: 1839 | D23: 0 | E23: 2 | F23: 15 | G23: 0 | J23: Samne wala Bari
A24: 20 | B24: 7546 | C24: 1777 | D24: 0 | E24: 3 | F24: 4 | G24: 0 | J24: Samne wala Bari
A25: 21 | B25: 7566 | C25: 1886 | D25: 0 | E25: 0 | F25: 18 | G25: 0 | J25: Doman Dasak Gharari
A26: 22 | B26: 7572 | C26: 1886 | D26: 0 | E26: 1 | F26: 3 | G26: 0 | J26: Doman Dasak Gharari
A27: 23 | B27: 7574 | C27: 1886 | D27: 0 | E27: 1 | F27: 3 | G27: 0 | J27: Doman Dasak Gharari
A28: 24 | B28: 7575 | C28: 1886 | D28: 0 | E28: 0 | F28: 9 | G28: 0 | J28: Doman Dasak Gharari
A29: 25 | B29: 7576 | C29: 1867 | D29: 0 | E29: 1 | F29: 7 | G29: 0 | J29: Samne wala Bari
A30: 26 | B30: 7577 | C30: 1867 | D30: 0 | E30: 0 | F30: 18 | G30: 0 | J30: Samne wala Bari
... A41: 37 | B41: 7796 | C41: 1773 | D41: 0 | E41: 1 | F41: 12 | G41: 0 | J41: Jhagraua Bari
C42: TOTAL | D42: 10 | E42: 6 | F42: 5 | G42: 0

Sheet RAKBA AS PER AMEEN
A1: S.NO | B1: KHATA NO | C1: KHESRA NO | E1: BIGGHA | F1: KATTHA | G1: DHOOR | H1: DHURKI
A2: 1 | B2: 2014 | C2: 707 | E2: 0 | F2: 11 | G2: 9 | H2: 0
A3: 2 | B3: 2014 | C3: 735 | E3: 0 | F3: 11 | G3: 14 | H3: 0
A4: 3 | B4: 1985 | C4: 767 | E4: 0 | F4: 5 | G4: 19 | H4: 0
A5: 4 | B5: 2014 | C5: 790 | E5: 0 | F5: 12 | G5: 12 | H5: 0
A6: 5 | B6: 2014 | C6: 792 | E6: 1 | F6: 3 | G6: 3 | H6: 0
A7: 6 | B7: 1892 | C7: 1007 | E7: 3 | F7: 16 | G7: 7 | H7: 0
A8: 7 | B8: 2014 | C8: 1179 | E8: 0 | F8: 4 | G8: 7 | H8: 0
A9: 8 | B9: 1889 | C9: 1187 | E9: 0 | F9: 2 | G9: 15 | H9: 0
A10: 9 | B10: 2039 | C10: 1189 | E10: 0 | F10: 2 | G10: 6 | H10: 0
A11: 10 | B11: 1889 | C11: 1190 | E11: 0 | F11: 6 | G11: 0 | H11: 0
A12: 11 | B12: 2014 | C12: 1246 | E12: 0 | F12: 2 | G12: 15 | H12: 0
A13: 12 | B13: 1993 | C13: 1247 | E13: 0 | F13: 3 | G13: 9 | H13: 0
... A21: 20 | B21: 1777 | C21: 7546 | E21: 0 | F21: 3 | G21: 4 | H21: 0
A22: 21 | B22: 1886 | C22: 7566 | D22: 1867 | E22: 0 | F22: 0 | G22: 18 | H22: 0
A23: 22 | B23: 1886 | C23: 7572 | E23: 0 | F23: 1 | G23: 3 | H23: 0
A24: 23 | B24: 1886 | C24: 7574 | E24: 0 | F24: 1 | G24: 3 | H24: 0
A25: 24 | B25: 1886 | C25: 7575 | E25: 0 | F25: 0 | G25: 9 | H25: 0
A26: 25 | B26: 1867 | C26: 7576 | D26: 1867 | E26: 0 | F26: 1 | G26: 7 | H26: 0
A27: 26 | B27: 1867 | C27: 7577 | E27: 0 | F27: 0 | G27: 18 | H27: 0
A28: 27 | B28: 1886 | C28: 7586 | E28: 0 | F28: 0 | G28: 5 | H28: 0
A29: 28 | B29: 1796 | C29: 7637 | E29: 0 | F29: 4 | G29: 16 | H29: 0
A30: 29 | B30: 1796 | C30: 7641 | E30: 0 | F30: 0 | G30: 9 | H30: 0
A31: 30 | B31: 1796 | C31: 7642 | E31: 0 | F31: 3 | G31: 0 | H31: 0
A32: 31 | B32: 1872 | C32: 7643 | E32: 0 | F32: 0 | G32: 5 | H32: 0
A33: 32 | B33: 1872 | C33: 7644 | E33: 0 | F33: 0 | G33: 14 | H33: 0
A34: 33 | B34: 1887 | C34: 7789 | E34: 0 | F34: 3 | G34: 4 | H34: 0
A35: 34 | B35: 1887 | C35: 7790 | E35: 0 | F35: 0 | G35: 18 | H35: 0
A36: 35 | B36: 2034 | C36: 7792 | E36: 0 | F36: 1 | G36: 3 | H36: 0
A37: 36 | B37: 1773 | C37: 7795 | D37: 1773 | E37: 0 | F37: 0 | G37: 14 | H37: 0
A38: 37 | B38: 1773 | C38: 7796 | D38: 1773 | E38: 0 | F38: 1 | G38: 12 | H38: 0

Sheet Sheet2
B1: LAND NAME | C1: KHATA | D1: KHESRA | E1: RAKBA | F1: IDENTIFIER | L1: 0.436 | M1: Decimal | N1: Dhur | P1: 1 Dhur | Q1: 0.2182
B2: Jhagraua Bari | C2: 1773 | D2: 7795 | E2: 14 Dhoor | F2: REWATINATH LAL + LEKHNATH LAL | L2: 4.5 | M2: 0.12 | N2: =M2*$L$2 -> 0.54
B3: Jhagraua Bari | C3: 1773 | D3: 7796 | E3: 1 kattha 12 Dhoor | F3: REWATINATH LAL + LEKHNATH LAL | M3: 0.14 | N3: =M3*$L$2 -> 0.63
B4: Neeras Lal Ke Gharari | C4: 1867 | D4: 7576 | E4: 1 Kattha + 7 Dhoor | F4: SAMNE WALA BARI | M4: 0.23 | N4: =M4*$L$2 -> 1.035
B5: Neeras Lal Ke Gharari | C5: 1867 | D5: 7577 | E5: 18 Dhoor | F5: SAMNE WALA BARI | N5: =SUM(N2:N4) -> 2.205
B6: Basobas (Purna Gharari) | C6: 1887 | D6: 7789 | E6: 3 Kattha 4 Dhoor | F6: AANAGAN
B7: Basobas (Purna Gharari) | C7: 1887 | D7: 7790 | E7: 18 Dhoor | F7: AANAGAN
B8: Dalaan Bari | C8: 1796 | D8: 7637 | E8: 4 Kattha 16 Dhoor | F8: UMANATH LAL
B9: Doman Das Gharari | C9: 1886 | D9: 7574 | E9: 1 Kattha + 3 Dhoor
B10: Doman Das Gharari | C10: 1886 | D10: 7566 | E10: 18 Dhoor | F10: BEL/ENAAR WALA BARI
B11: Doman Das Gharari | C11: 1886 | D11: 7572 | E11: 1 Kattha + 3 Dhoor
B12: Doman Das Gharari | C12: 1886 | D12: 7575 | E12: 9 Dhoor | I12: 497/707 ansh | K12: 0.0875
B13: Doman Das Gharari | C13: 1886 | D13: 7586 | E13: 5 Dhoor | I13: 498/707 ansh | K13: 0.089
B14: Dalaan Bari | C14: 1872 | D14: 7643 | E14: 5 Dhoor | F14: REWATINATH LAL | K14: =SUM(K12:K13) -> 0.1765
B15: Dalaan Bari | C15: 1872 | D15: 7644 | E15: 14 Dhoor | F15: REWATINATH LAL | K15: =K14/3 -> 0.058833333
B16: PUBARIA KALAM | C16: 1993 | D16: 1247 | E16: 3 KATTHA 9 DHOOR | F16: UMANATH LAL
B17: PUBARIA KALAM | C17: 2033 | D17: 1249 | E17: 18 DHOOR | F17: UMANATH LAL
B18: DADA GHARARI | C18: 1993 | D18: 7528 | E18: 2 KATTHA 15 DHOOR | F18: SAJHI [MANDIR WALA GHARARI]
B19: DADA GHARARI | C19: 1993 | D19: 7529 | E19: 18 DHOOR
B20: DADA GHARARI | C20: 1993 | D20: 7530 | E20: 1 KATTHA 12 DHOOR

Sheet Sheet1
A1: 267
A2: 62 | E2: KATTHA | F2: DHUR
A3: =SUM(A1:A2) -> 329 | B3: =A3/2 -> 164.5 | C3: =B3/3 -> 54.833333 | E3: 0 | F3: 10
E4: 0 | F4: 18
E5: 0 | F5: 16.2
E6: 0 | F6: 18.9
E7: 12 | F7: 10
E8: 1 | F8: 10
E9: 0 | F9: 10
F10: 18
E11: 0 | F11: 16.2
E12: 0 | F12: 18.2
E13: 12 | F13: 10
E14: 1 | F14: 10
E15: 1 | F15: 11
E16: 0 | F16: 16.4
E17: 0 | F17: 18.9
E18: 12 | F18: 10
E19: 1 | F19: 10
E20: =SUM(E3:E19) -> 40 | F20: =SUM(F3:F19) -> 231.8
E21: 51 | F21: =232/20 -> 11.6
